Workbook

Sheet Balance Sheet
B1: Balance Sheet ( All Amount in ₹ CR, Unless otherwise stated)
B3: Assets | C3: FY18 | D3: FY19 | E3: FY20 | F3: FY21 | G3: FY22 | H3: FY23 | I3: FY24 | J3: FY25E | K3: FY26E | L3: FY27E | M3: FY28E | N3: FY29E
B4: Non-current assets
A5: Capex | B5: Property, plant and equipment | C5: 264 | D5: 214 | E5: 14790 | F5: 14178 | G5: 12826 | H5: 26803 | I5: 26798 | J5: =Schedules_Populated!J71 -> 28150.664 | K5: =Schedules_Populated!K71 -> 30751.19 | L5: =Schedules_Populated!L71 -> 32972.031 | M5: =Schedules_Populated!M71 -> 35918.426 | N5: =Schedules_Populated!N71 -> 39023.19
B6: Capital work in progress | C6: 14 | D6: 0 | E6: 1344 | F6: 1199 | G6: 2646 | H6: 4054 | I6: 7504 | J6: =Assumptions!J22 -> 4736.7 | K6: =Assumptions!K22 -> 4935.78 | L6: =Assumptions!L22 -> 4815.722 | M6: =Assumptions!M22 -> 5036.4928 | N6: =Assumptions!N22 -> 5176.9617
B7: Goodwill | C7: 2961 | D7: 1736 | E7: 0 | F7: 0 | G7: 0 | H7: 0 | I7: 0 | J7: =Assumptions!J23 -> 0 | K7: =Assumptions!K23 -> 0 | L7: =Assumptions!L23 -> 0 | M7: =Assumptions!M23 -> 0 | N7: =Assumptions!N23 -> 0
A8: Capex | B8: Other Intangible assets | C8: 793 | D8: 196 | E8: 336 | F8: 224 | G8: 350 | H8: 548 | I8: 454 | J8: =Schedules_Populated!J72 -> 517.97957 | K8: =Schedules_Populated!K72 -> 610.12824 | L8: =Schedules_Populated!L72 -> 699.64408 | M8: =Schedules_Populated!M72 -> 817.77078 | N8: =Schedules_Populated!N72 -> 950.083
B9: Intangible assets under development | C9: 0 | D9: 17 | E9: 71 | F9: 298 | G9: 290 | H9: 89 | I9: 230 | J9: =Assumptions!J24 -> 184.6 | K9: =Assumptions!K24 -> 210.54 | L9: =Assumptions!L24 -> 200.496 | M9: =Assumptions!M24 -> 193.7204 | N9: =Assumptions!N24 -> 200.15096
A10: Capex | B10: Right of use assets | C10: 5484 | D10: 3965 | E10: 618 | F10: 586 | G10: 571 | H10: 591 | I10: 613 | J10: =Schedules_Populated!J73 -> 626.96075 | K10: =Schedules_Populated!K73 -> 637.3457 | L10: =Schedules_Populated!L73 -> 645.69404 | M10: =Schedules_Populated!M73 -> 655.31396 | N10: =Schedules_Populated!N73 -> 664.29856
B11: Financial Assets
B12: i. Investments | E12: 36269 | F12: 34529 | G12: 37935 | H12: 49184 | I12: 53384
B13: ii. Loans | C13: 585 | D13: 618 | E13: 0.2 | F13: 0.2 | G13: 0.2 | H13: 0.2 | I13: 0.1 | J13: =Assumptions!J27 -> 0.16 | K13: =Assumptions!K27 -> 0.154 | L13: =Assumptions!L27 -> 0.1596 | M13: =Assumptions!M27 -> 0.15604 | N13: =Assumptions!N27 -> 0.151696
B14: iii. Other Financial assets | C14: 185 | D14: 239 | E14: 36.5 | F14: 37 | G14: 37.5 | H14: 240 | I14: 298 | J14: =Assumptions!J28 -> 202.3 | K14: =Assumptions!K28 -> 201.77 | L14: =Assumptions!L28 -> 198.948 | M14: =Assumptions!M28 -> 214.1402 | N14: =Assumptions!N28 -> 215.54748
B15: Income tax assets (net) | C15: 584 | D15: 920 | E15: 0 | F15: 541 | G15: 545 | H15: 605 | I15: 584 | J15: =Assumptions!J29 -> 523.7 | K15: =Assumptions!K29 -> 553.78 | L15: =Assumptions!L29 -> 552.022 | M15: =Assumptions!M29 -> 558.2128 | N15: =Assumptions!N29 -> 555.03972
B16: Other Assets | C16: 40 | D16: 48 | E16: 1722 | F16: 1687 | G16: 2520 | H16: 2323 | I16: 2805 | J16: =Assumptions!J30 -> 2411.8 | K16: =Assumptions!K30 -> 2459.22 | L16: =Assumptions!L30 -> 2472.028 | M16: =Assumptions!M30 -> 2480.5572 | N16: =Assumptions!N30 -> 2501.4333
B17: Deferred tax assets (net) | C17: 0 | D17: 0 | E17: 0 | F17: 0 | G17: 141 | H17: 279 | I17: 47 | J17: =Assumptions!J31 -> 116.6 | K17: =Assumptions!K31 -> 102.74 | L17: =Assumptions!L31 -> 122.776 | M17: =Assumptions!M31 -> 124.1924 | N17: =Assumptions!N31 -> 113.14376
B18: Total Non-current assets | C18: =SUM(C5:C17) -> 10910 | D18: =SUM(D5:D17) -> 7953 | E18: =SUM(E5:E17) -> 55186.7 | F18: =SUM(F5:F17) -> 53279.2 | G18: =SUM(G5:G17) -> 57861.7 | H18: =SUM(H5:H17) -> 84716.2 | I18: =SUM(I5:I17) -> 92717.1 | J18: =SUM(J5:J17) -> 37471.465 | ... N18: =SUM(N5:N17) -> 49400.001
B19: Current assets
B20: Inventories | E20: 3214 | F20: 3049 | G20: 3532 | H20: 5443 | I20: 5318
B21: Financial assets
B22: i. Investments | C22: 13862 | D22: 9815 | E22: 1219 | F22: 8416 | G22: 4100 | H22: 0 | I22: 3912 | J22: =Schedules_Populated!J5 -> 4019.6356 | K22: =Schedules_Populated!K5 -> 3878.0218 | L22: =Schedules_Populated!L5 -> 3552.1879 | M22: =Schedules_Populated!M5 -> 3813.3642 | N22: =Schedules_Populated!N5 -> 3842.7031
B23: ii. Trade receivables | C23: 9437 | D23: 12927 | E23: 1978 | F23: 1280 | G23: 2034 | H23: 3285 | I23: 4597 | J23: =Schedules_Populated!J6 -> 4076.2619 | K23: =Schedules_Populated!K6 -> 4037.7646 | L23: =Schedules_Populated!L6 -> 4038.4393 | M23: =Schedules_Populated!M6 -> 4149.872 | N23: =Schedules_Populated!N6 -> 4271.9013
B24: iii. Cash and cash equivalents | C24: 1652 | D24: 2627 | E24: 21 | F24: 41 | G24: 35 | H24: 1785 | I24: 2660 | J24: =CFS!B20 -> 24815.649 | K24: =CFS!C20 -> 50730.112 | L24: =CFS!D20 -> 87073.599 | M24: =CFS!E20 -> 133840.83 | N24: =CFS!F20 -> 193982.31
B25: iv. Loans | C25: 273 | D25: 77 | E25: 17 | F25: 23 | G25: 30.5 | H25: 30 | I25: 33 | J25: =Schedules_Populated!J7 -> 37.639332 | K25: =Schedules_Populated!K7 -> 38.574388 | L25: =Schedules_Populated!L7 -> 38.722962 | M25: =Schedules_Populated!M7 -> 38.272128 | N25: =Schedules_Populated!N7 -> 39.00615
B26: v. Other financial assets | C26: 1141 | D26: 7091 | E26: 660 | F26: 1324 | G26: 2593 | H26: 2602 | I26: 3419 | J26: =Schedules_Populated!J8 -> 3412.7871 | K26: =Schedules_Populated!K8 -> 3496.1631 | L26: =Schedules_Populated!L8 -> 3435.0408 | M26: =Schedules_Populated!M8 -> 3493.6732 | N26: =Schedules_Populated!N8 -> 3563.6517
B27: vi. Other Bank Balances | E27: 8 | F27: 3006 | G27: 3007 | H27: 963 | I27: 168 | J27: 57687 | K27: 57687 | L27: 57687 | M27: 57687 | N27: 57687
B28: Other assets | C28: 1424 | D28: 862 | E28: 1325 | F28: 958 | G28: 1461 | H28: 1560 | I28: 2508 | J28: =Schedules_Populated!J9 -> 2297.1213 | K28: =Schedules_Populated!K9 -> 2314.9107 | L28: =Schedules_Populated!L9 -> 2299.1559 | M28: =Schedules_Populated!M9 -> 2315.4248 | N28: =Schedules_Populated!N9 -> 2400.4881
B29: Assets classified as held for Sale | H29: 0 | I29: 20
B30: Total current assets | C30: =SUM(C22:C28) -> 27789 | D30: =SUM(D22:D28) -> 33399 | E30: =SUM(E20:E28) -> 8442 | F30: =SUM(F20:F28) -> 18097 | G30: =SUM(G20:G28) -> 16792.5 | H30: =SUM(H20:H29) -> 15668 | I30: =SUM(I20:I29) -> 22635 | J30: =SUM(J22:J28) -> 96346.094 | K30: =SUM(K22:K28) -> 122182.55 | L30: =SUM(L22:L28) -> 158124.15 | M30: =SUM(M22:M28) -> 205338.43 | N30: =SUM(N22:N28) -> 265787.06
B31: Total assets | C31: =C18+C30 -> 38699 | D31: =D18+D30 -> 41352 | E31: =E18+E30 -> 63628.7 | F31: =F18+F30 -> 71376.2 | G31: =G18+G30 -> 74654.2 | H31: =H18+H30 -> 100384.2 | I31: =I18+I30 -> 115352.1 | J31: =J18+J30 -> 133817.56 | ... N31: =N18+N30 -> 315187.06
B32: Equity and liabilities
B33: Equity
B34: Equity share capital | C34: 375 | D34: 597 | E34: 151 | F34: 151 | G34: 151 | H34: 157 | I34: 157 | J34: =Assumptions!L34 -> 157 | K34: =Assumptions!K34 -> 157 | L34: =Assumptions!L34 -> 157 | M34: =Assumptions!M34 -> 157 | N34: =Assumptions!N34 -> 157
B35: Non controlling Interest | C35: 2229 | D35: 2230 | E35: 19 | F35: 0 | G35: 0 | H35: 0 | I35: 0 | J35: =Assumptions!J35 -> 0 | K35: =Assumptions!K35 -> 0 | L35: =Assumptions!L35 -> 0 | M35: =Assumptions!M35 -> 0 | N35: =Assumptions!N35 -> 0
B36: Other equity | C36: -13492 | D36: -9432 | E36: 49262 | F36: 52350 | G36: 55182 | H36: 74443 | I36: 85479 | J36: =Assumptions!J36 -> 105098.36 | K36: =Assumptions!K36 -> 133419.27 | L36: =Assumptions!L36 -> 171973.64 | M36: =Assumptions!M36 -> 222138.3 | N36: =Assumptions!N36 -> 285395.03
B37: Total Equity | C37: =SUM(C34:C36) -> -10888 | D37: =SUM(D34:D36) -> -6605 | E37: =SUM(E34:E36) -> 49432 | F37: =SUM(F34:F36) -> 52501 | G37: =SUM(G34:G36) -> 55333 | H37: =SUM(H34:H36) -> 74600 | I37: =SUM(I34:I36) -> 85636 | J37: =SUM(J34:J36) -> 105255.36 | ... N37: =SUM(N34:N36) -> 285552.03
B38: Liabilities
B39: Non-current Liabilities
B40: Financial Liabilities
B41: i. Borrowings | C41: 1483 | D41: 850 | E41: 5 | F41: 2.8 | G41: 0 | H41: 0 | I41: 0 | J41: =Schedules_Populated!J42 -> 0.12099114 | K41: =Schedules_Populated!K42 -> 0.049258597 | L41: =Schedules_Populated!L42 -> 0.0038212058 | M41: =Schedules_Populated!M42 -> 0.005140706 | N41: =Schedules_Populated!N42 -> 0.041393374
...

Sheet CFS
A1: Cash Flow Statement ( All Amount in ₹ Crores, Unless otherwise stated) | B1: 2025E | C1: 2026E | D1: 2027E | E1: 2028E | F1: 2029E
A2: Net Profit | B2: ='Profit & Loss Statement'!J25 -> 19619.362 | C2: ='Profit & Loss Statement'!K25 -> 28320.909 | D2: ='Profit & Loss Statement'!L25 -> 38554.371 | E2: ='Profit & Loss Statement'!M25 -> 50164.654 | F2: ='Profit & Loss Statement'!N25 -> 63256.735 | H2: I/S
A3: Add Finance Costs | B3: ='Profit & Loss Statement'!J12 -> 208.42213 | C3: ='Profit & Loss Statement'!K12 -> 208.0012 | D3: ='Profit & Loss Statement'!L12 -> 232.38795 | E3: ='Profit & Loss Statement'!M12 -> 242.84088 | F3: ='Profit & Loss Statement'!N12 -> 240.07668 | H3: I/S
A4: Add Depreciation | B4: ='Profit & Loss Statement'!J11 -> 6453.3954 | C4: ='Profit & Loss Statement'!K11 -> 6977.0334 | D4: ='Profit & Loss Statement'!L11 -> 8146.8453 | E4: ='Profit & Loss Statement'!M11 -> 9146.126 | F4: ='Profit & Loss Statement'!N11 -> 10473.128 | H4: I/S | I4: Derived Statement
A5: Less Change in Net Working Capital | B5: =-Schedules_Populated!J22 -> 1217.3735 | C5: =-Schedules_Populated!K22 -> 573.95802 | D5: =-Schedules_Populated!L22 -> 56.371516 | E5: =-Schedules_Populated!M22 -> -151.08202 | F5: =-Schedules_Populated!N22 -> 253.61227 | H5: WC Schedule/BS
A6: Cash Flow from Operating Activities | B6: =SUM(B2:B5) -> 27498.553 | C6: =SUM(C2:C5) -> 36079.902 | D6: =SUM(D2:D5) -> 46989.975 | E6: =SUM(E2:E5) -> 59402.539 | F6: =SUM(F2:F5) -> 74223.552
A8: Other Changes in Investments/Liabilitie/Others | B8: =SUM('Balance Sheet'!I6:I7,'Balance Sheet'!I9,'Balance Sheet'!I13:I17,'Balance Sheet'!J43:J45)-SUM('Balance Sheet'!J6:J7,'Balance Sheet'!J9,'Balance Sheet'!J13:J17,'Balance Sheet'!I43:I45) -> 2743.54 | C8: =SUM('Balance Sheet'!J6:J7,'Balance Sheet'!J9,'Balance Sheet'!J13:J17,'Balance Sheet'!K43:K45)-SUM('Balance Sheet'!K6:K7,'Balance Sheet'!K9,'Balance Sheet'!K13:K17,'Balance Sheet'!J43:J45) -> -280.004 | D8: =SUM('Balance Sheet'!K6:K7,'Balance Sheet'!K9,'Balance Sheet'!K13:K17,'Balance Sheet'!L43:L45)-SUM('Balance Sheet'!L6:L7,'Balance Sheet'!L9,'Balance Sheet'!L13:L17,'Balance Sheet'!K43:K45) -> 48.1704 | E8: =SUM('Balance Sheet'!L6:L7,'Balance Sheet'!L9,'Balance Sheet'!L13:L17,'Balance Sheet'!M43:M45)-SUM('Balance Sheet'!M6:M7,'Balance Sheet'!M9,'Balance Sheet'!M13:M17,'Balance Sheet'!L43:L45) -> -176.11904 | F8: =SUM('Balance Sheet'!M6:M7,'Balance Sheet'!M9,'Balance Sheet'!M13:M17,'Balance Sheet'!N43:N45)-SUM('Balance Sheet'!N6:N7,'Balance Sheet'!N9,'Balance Sheet'!N13:N17,'Balance Sheet'!M43:M45) -> -127.1329
A9: Capital Expenditure | B9: =-Schedules_Populated!J106 -> -7884 | C9: =-Schedules_Populated!K106 -> -9680.0931 | D9: =-Schedules_Populated!L106 -> -10465.55 | E9: =-Schedules_Populated!M106 -> -12220.268 | F9: =-Schedules_Populated!N106 -> -13719.189 | H9: Capex Schedule/BS
A10: Cash Flow from Investing Activities | B10: =B9+B8 -> -5140.46 | C10: =C9+C8 -> -9960.0971 | D10: =D9+D8 -> -10417.38 | E10: =E9+E8 -> -12396.387 | F10: =F9+F8 -> -13846.322
A12: Changes to Equity | B12: ='Balance Sheet'!J34-'Balance Sheet'!I34 -> 0 | C12: ='Balance Sheet'!K34-'Balance Sheet'!J34 -> 0 | D12: ='Balance Sheet'!L34-'Balance Sheet'!K34 -> 0 | E12: ='Balance Sheet'!M34-'Balance Sheet'!L34 -> 0 | F12: ='Balance Sheet'!N34-'Balance Sheet'!M34 -> 0 | H12: B/S
A13: Net Loans Raised for the long term | B13: =Schedules_Populated!J61+Schedules_Populated!J66 -> 5.978134 | C13: =Schedules_Populated!K61+Schedules_Populated!K66 -> 2.6593248 | D13: =Schedules_Populated!L61+Schedules_Populated!L66 -> 3.2797592 | E13: =Schedules_Populated!M61+Schedules_Populated!M66 -> 3.9161798 | F13: =Schedules_Populated!N61+Schedules_Populated!N66 -> 4.328686
A14: Finance Costs Paid | B14: =-B3 -> -208.42213 | C14: =-C3 -> -208.0012 | D14: =-D3 -> -232.38795 | E14: =-E3 -> -242.84088 | F14: =-F3 -> -240.07668 | H14: I/S
A15: Dividend Paid | B15: 0 | C15: 0 | D15: 0 | E15: 0 | F15: 0 | H15: I/S
A16: Cash Flow from Financing Activities | B16: =SUM(B12:B15) -> -202.444 | C16: =SUM(C12:C15) -> -205.34187 | D16: =SUM(D12:D15) -> -229.10819 | E16: =SUM(E12:E15) -> -238.9247 | F16: =SUM(F12:F15) -> -235.748
A18: Total Cash Flow | B18: =B6+B10+B16 -> 22155.649 | C18: =C6+C10+C16 -> 25914.463 | D18: =D6+D10+D16 -> 36343.487 | E18: =E6+E10+E16 -> 46767.228 | F18: =F6+F10+F16 -> 60141.482
A19: Beginning Cash Balance | B19: ='Balance Sheet'!I24 -> 2660 | C19: ='Balance Sheet'!J24 -> 24815.649 | D19: ='Balance Sheet'!K24 -> 50730.112 | E19: ='Balance Sheet'!L24 -> 87073.599 | F19: ='Balance Sheet'!M24 -> 133840.83 | H19: B/S
A20: Closing Cash Balance in Balance Sheet | B20: =B18+B19 -> 24815.649 | C20: =C18+C19 -> 50730.112 | D20: =D18+D19 -> 87073.599 | E20: =E18+E19 -> 133840.83 | F20: =F18+F19 -> 193982.31

Sheet Schedules_Populated
B2: Working Capital Schedule | C2: FY18 | D2: FY19 | E2: FY20 | F2: FY21 | G2: FY22 | H2: FY23 | I2: FY24 | J2: FY25E | K2: FY26E | L2: FY27E | M2: FY28E | N2: FY29E
B3: Current assets (except cash & equivalents)
B4: Financial assets
B5: i. Investments | C5: ='Balance Sheet'!C22 -> 13862 | D5: ='Balance Sheet'!D22 -> 9815 | E5: ='Balance Sheet'!E22 -> 1219 | F5: ='Balance Sheet'!F22 -> 8416 | G5: ='Balance Sheet'!G22 -> 4100 | H5: ='Balance Sheet'!H22 -> 0 | I5: ='Balance Sheet'!I22 -> 3912 | J5: =J25*'Profit & Loss Statement'!J$5/365 -> 4019.6356 | K5: =K25*'Profit & Loss Statement'!K$5/365 -> 3878.0218 | L5: =L25*'Profit & Loss Statement'!L$5/365 -> 3552.1879 | M5: =M25*'Profit & Loss Statement'!M$5/365 -> 3813.3642 | N5: =N25*'Profit & Loss Statement'!N$5/365 -> 3842.7031 | P5: How to forecast forecast WC Schedule
B6: ii. Trade receivables | C6: ='Balance Sheet'!C23 -> 9437 | D6: ='Balance Sheet'!D23 -> 12927 | E6: ='Balance Sheet'!E23 -> 1978 | F6: ='Balance Sheet'!F23 -> 1280 | G6: ='Balance Sheet'!G23 -> 2034 | H6: ='Balance Sheet'!H23 -> 3285 | I6: ='Balance Sheet'!I23 -> 4597 | J6: =J26*'Profit & Loss Statement'!J$5/365 -> 4076.2619 | K6: =K26*'Profit & Loss Statement'!K$5/365 -> 4037.7646 | L6: =L26*'Profit & Loss Statement'!L$5/365 -> 4038.4393 | M6: =M26*'Profit & Loss Statement'!M$5/365 -> 4149.872 | N6: =N26*'Profit & Loss Statement'!N$5/365 -> 4271.9013 | P6: 1. Convert CA/CL into DSO | S6: DSO = (CA/CL)x365/Sales
B7: iii. Loans | C7: ='Balance Sheet'!C25 -> 273 | D7: ='Balance Sheet'!D25 -> 77 | E7: ='Balance Sheet'!E25 -> 17 | F7: ='Balance Sheet'!F25 -> 23 | G7: ='Balance Sheet'!G25 -> 30.5 | H7: ='Balance Sheet'!H25 -> 30 | I7: ='Balance Sheet'!I25 -> 33 | J7: =J27*'Profit & Loss Statement'!J$5/365 -> 37.639332 | K7: =K27*'Profit & Loss Statement'!K$5/365 -> 38.574388 | L7: =L27*'Profit & Loss Statement'!L$5/365 -> 38.722962 | M7: =M27*'Profit & Loss Statement'!M$5/365 -> 38.272128 | N7: =N27*'Profit & Loss Statement'!N$5/365 -> 39.00615 | P7: 2. Forecast the DSO
B8: iv. Other financial assets | C8: ='Balance Sheet'!C26 -> 1141 | D8: ='Balance Sheet'!D26 -> 7091 | E8: ='Balance Sheet'!E26 -> 660 | F8: ='Balance Sheet'!F26 -> 1324 | G8: ='Balance Sheet'!G26 -> 2593 | H8: ='Balance Sheet'!H26 -> 2602 | I8: ='Balance Sheet'!I26 -> 3419 | J8: =J28*'Profit & Loss Statement'!J$5/365 -> 3412.7871 | K8: =K28*'Profit & Loss Statement'!K$5/365 -> 3496.1631 | L8: =L28*'Profit & Loss Statement'!L$5/365 -> 3435.0408 | M8: =M28*'Profit & Loss Statement'!M$5/365 -> 3493.6732 | N8: =N28*'Profit & Loss Statement'!N$5/365 -> 3563.6517 | P8: 3. Calculate Forecasted CA/CL from Forecasted DSO | S8: (CA/CL) = DSOxSales/365
B9: Other assets | C9: ='Balance Sheet'!C28 -> 1424 | D9: ='Balance Sheet'!D28 -> 862 | E9: ='Balance Sheet'!E28 -> 1325 | F9: ='Balance Sheet'!F28 -> 958 | G9: ='Balance Sheet'!G28 -> 1461 | H9: ='Balance Sheet'!H28 -> 1560 | I9: ='Balance Sheet'!I28 -> 2508 | J9: =J29*'Profit & Loss Statement'!J$5/365 -> 2297.1213 | K9: =K29*'Profit & Loss Statement'!K$5/365 -> 2314.9107 | L9: =L29*'Profit & Loss Statement'!L$5/365 -> 2299.1559 | M9: =M29*'Profit & Loss Statement'!M$5/365 -> 2315.4248 | N9: =N29*'Profit & Loss Statement'!N$5/365 -> 2400.4881
B10: Total Current Assets (except cash & equivalents) | C10: =SUM(C5:C9) -> 26137 | D10: =SUM(D5:D9) -> 30772 | E10: =SUM(E5:E9) -> 5199 | F10: =SUM(F5:F9) -> 12001 | G10: =SUM(G5:G9) -> 10218.5 | H10: =SUM(H5:H9) -> 7477 | I10: =SUM(I5:I9) -> 14469 | J10: =SUM(J5:J9) -> 13843.445 | ... N10: =SUM(N5:N9) -> 14117.75
B11: Current Liabilities
B12: Outstanding Dues of creditors & Enterprises | C12: ='Balance Sheet'!C48 -> 547 | D12: ='Balance Sheet'!D48 -> 1067 | E12: ='Balance Sheet'!E48 -> 7500 | F12: ='Balance Sheet'!F48 -> 10168 | G12: ='Balance Sheet'!G48 -> 9765 | H12: ='Balance Sheet'!H48 -> 13675 | I12: ='Balance Sheet'!I48 -> 16988 | J12: =J31*'Profit & Loss Statement'!J$5/365 -> 17160.543 | K12: =K31*'Profit & Loss Statement'!K$5/365 -> 17436.854 | L12: =L31*'Profit & Loss Statement'!L$5/365 -> 17113.234 | M12: =M31*'Profit & Loss Statement'!M$5/365 -> 17385.059 | N12: =N31*'Profit & Loss Statement'!N$5/365 -> 17779.4 | P12: DSO = (CA or CL)x365/Sales
B13: Financial Liabilities | P13: (CA/CL) = DSOxSales/365
B14: i. Borrowings | C14: ='Balance Sheet'!C50 -> 6855 | D14: ='Balance Sheet'!D50 -> 6012 | E14: ='Balance Sheet'!E50 -> 106 | F14: ='Balance Sheet'!F50 -> 489 | G14: ='Balance Sheet'!G50 -> 382 | H14: ='Balance Sheet'!H50 -> 1216 | I14: ='Balance Sheet'!I50 -> 33 | J14: =J43 -> 34.529009 | K14: =K43 -> 36.333241 | L14: =L43 -> 38.197804 | M14: =M43 -> 40.106566 | N14: =N43 -> 42.075898
B15: ii. Lease Liabilities | C15: ='Balance Sheet'!C51 -> 1456 | D15: ='Balance Sheet'!D51 -> 1582 | E15: ='Balance Sheet'!E51 -> 10 | F15: ='Balance Sheet'!F51 -> 7.4 | G15: ='Balance Sheet'!G51 -> 8 | H15: ='Balance Sheet'!H51 -> 7 | I15: ='Balance Sheet'!I51 -> 18 | J15: =J47 -> 16.392857 | K15: =K47 -> 18.1243 | L15: =L47 -> 19.484728 | M15: =M47 -> 20.489774 | N15: =N47 -> 21.363242
B16: iii. Trade payables | C16: ='Balance Sheet'!C52 -> 2498 | D16: ='Balance Sheet'!D52 -> 2878 | E16: ='Balance Sheet'!E52 -> 0 | F16: ='Balance Sheet'!F52 -> 0 | G16: ='Balance Sheet'!G52 -> 0 | H16: ='Balance Sheet'!H52 -> 0 | I16: ='Balance Sheet'!I52 -> 0 | J16: =J35*'Profit & Loss Statement'!J$5/365 -> 0 | K16: =K35*'Profit & Loss Statement'!K$5/365 -> 0 | L16: =L35*'Profit & Loss Statement'!L$5/365 -> 0 | M16: =M35*'Profit & Loss Statement'!M$5/365 -> 0 | N16: =N35*'Profit & Loss Statement'!N$5/365 -> 0 | P16: Whenever we are forecasting on the basis of Average
B17: iv. Other Financial liabilities | C17: ='Balance Sheet'!C53 -> 30008 | D17: ='Balance Sheet'!D53 -> 29930 | E17: ='Balance Sheet'!E53 -> 904 | F17: ='Balance Sheet'!F53 -> 1272 | G17: ='Balance Sheet'!G53 -> 2027 | H17: ='Balance Sheet'!H53 -> 2290 | I17: ='Balance Sheet'!I53 -> 2224 | J17: =J36*'Profit & Loss Statement'!J$5/365 -> 2526.8571 | K17: =K36*'Profit & Loss Statement'!K$5/365 -> 2566.6115 | L17: =L36*'Profit & Loss Statement'!L$5/365 -> 2621.7014 | M17: =M36*'Profit & Loss Statement'!M$5/365 -> 2606.3595 | N17: =N36*'Profit & Loss Statement'!N$5/365 -> 2639.1374
B18: Provisions | C18: ='Balance Sheet'!C54 -> 820 | D18: ='Balance Sheet'!D54 -> 998 | E18: ='Balance Sheet'!E54 -> 681 | F18: ='Balance Sheet'!F54 -> 743 | G18: ='Balance Sheet'!G54 -> 861 | H18: ='Balance Sheet'!H54 -> 1083 | I18: ='Balance Sheet'!I54 -> 1312 | J18: =J37*'Profit & Loss Statement'!J$5/365 -> 1363.6489 | K18: =K37*'Profit & Loss Statement'!K$5/365 -> 1374.0811 | L18: =L37*'Profit & Loss Statement'!L$5/365 -> 1364.9136 | M18: =M37*'Profit & Loss Statement'!M$5/365 -> 1375.6534 | N18: =N37*'Profit & Loss Statement'!N$5/365 -> 1406.799 | P18: If it is Balance Sheet
B19: Other current liabilities | C19: ='Balance Sheet'!C55 -> 671 | D19: ='Balance Sheet'!D55 -> 736 | E19: ='Balance Sheet'!E55 -> 1409 | F19: ='Balance Sheet'!F55 -> 2680 | G19: ='Balance Sheet'!G55 -> 2869 | H19: ='Balance Sheet'!H55 -> 3337 | I19: ='Balance Sheet'!I55 -> 4175 | J19: =J38*'Profit & Loss Statement'!J$5/365 -> 4239.8479 | K19: =K38*'Profit & Loss Statement'!K$5/365 -> 4405.7618 | L19: =L38*'Profit & Loss Statement'!L$5/365 -> 4334.7185 | M19: =M38*'Profit & Loss Statement'!M$5/365 -> 4360.5591 | N19: =N38*'Profit & Loss Statement'!N$5/365 -> 4460.2083 | P19: Use Weighted Average
B20: Total Current Liabilities | C20: =SUM(C12:C19) -> 42855 | D20: =SUM(D12:D19) -> 43203 | E20: =SUM(E12:E19) -> 10610 | F20: =SUM(F12:F19) -> 15359.4 | G20: =SUM(G12:G19) -> 15912 | H20: =SUM(H12:H19) -> 21608 | I20: =SUM(I12:I19) -> 24750 | J20: =SUM(J12:J19) -> 25341.819 | ... N20: =SUM(N12:N19) -> 26348.984 | P20: Because I want to give more weightage to receny years, as balance sheet is not that volatile
B21: Net Working Capital (excluding cash) | C21: =C10-C20 -> -16718 | D21: =D10-D20 -> -12431 | E21: =E10-E20 -> -5411 | F21: =F10-F20 -> -3358.4 | G21: =G10-G20 -> -5693.5 | H21: =H10-H20 -> -14131 | I21: =I10-I20 -> -10281 | J21: =J10-J20 -> -11498.374 | ... N21: =N10-N20 -> -12231.233 | P21: If it's p&L Statement use Simple average
B22: Changes in Net Working Capital | D22: =D21-C21 -> 4287 | E22: =E21-D21 -> 7020 | F22: =F21-E21 -> 2052.6 | G22: =G21-F21 -> -2335.1 | H22: =H21-G21 -> -8437.5 | I22: =I21-H21 -> 3850 | J22: =J21-I21 -> -1217.3735 | K22: =K21-J21 -> -573.95802 | ... N22: =N21-M21 -> -253.61227
A23: DSO | B23: Current Asset as days of sales | C23: =C2 -> FY18 | D23: =D2 -> FY19 | E23: =E2 -> FY20 | F23: =F2 -> FY21 | G23: =G2 -> FY22 | H23: =H2 -> FY23 | I23: =I2 -> FY24 | J23: =J2 -> FY25E | ... N23: =N2 -> FY29E
B24: Financial assets
B25: i. Investments | C25: =C5*365/'Profit & Loss Statement'!C$5 -> 108.20192 | D25: =D5*365/'Profit & Loss Statement'!D$5 -> 60.682888 | E25: =E5*365/'Profit & Loss Statement'!E$5 -> 5.8807164 | F25: =F5*365/'Profit & Loss Statement'!F$5 -> 43.651452 | G25: =G5*365/'Profit & Loss Statement'!G$5 -> 16.942149 | H25: =H5*365/'Profit & Loss Statement'!H$5 -> 0 | I25: =I5*365/'Revenue Model'!I$3 -> 10.065559 | J25: =I25*40%+H25*40%+G25*10%+F25*10% -> 10.085584 | K25: =J25*40%+I25*40%+H25*10%+G25*10% -> 9.7546717 | L25: =K25*40%+J25*40%+I25*10%+H25*10% -> 8.9426579 | M25: =L25*40%+K25*40%+J25*10%+I25*10% -> 9.494046 | N25: =M25*40%+L25*40%+K25*10%+J25*10% -> 9.3587071
B26: ii. Trade receivables | C26: =C6*365/'Profit & Loss Statement'!C$5 -> 73.661919 | D26: =D6*365/'Profit & Loss Statement'!D$5 -> 79.923352 | E26: =E6*365/'Profit & Loss Statement'!E$5 -> 9.5422945 | F26: =F6*365/'Profit & Loss Statement'!F$5 -> 6.6390041 | G26: =G6*365/'Profit & Loss Statement'!G$5 -> 8.4049587 | H26: =H6*365/'Profit & Loss Statement'!H$5 -> 10.126045 | I26: =I6*365/'Revenue Model'!I$3 -> 11.82806 | J26: =I26*40%+H26*30%+G26*10%+F26*10%+E26*10% -> 10.227663 | K26: =J26*40%+I26*30%+H26*10%+G26*10%+F26*10% -> 10.156484 | L26: =K26*40%+J26*30%+I26*10%+H26*10%+G26*10% -> 10.166799 | M26: =L26*40%+K26*30%+J26*10%+I26*10%+H26*10% -> 10.331842 | N26: =M26*40%+L26*30%+K26*10%+J26*10%+I26*10% -> 10.403997
B27: iii. Loans | C27: =C7*365/'Profit & Loss Statement'!C$5 -> 2.1309425 | D27: =D7*365/'Profit & Loss Statement'!D$5 -> 0.47606545 | E27: =E7*365/'Profit & Loss Statement'!E$5 -> 0.082011631 | F27: =F7*365/'Profit & Loss Statement'!F$5 -> 0.11929461 | G27: =G7*365/'Profit & Loss Statement'!G$5 -> 0.12603306 | H27: =H7*365/'Profit & Loss Statement'!H$5 -> 0.092475298 | I27: =I7*365/'Revenue Model'!I$3 -> 0.084908853 | J27: =I27*40%+H27*30%+G27*10%+F27*10%+E27*10% -> 0.09444006 | K27: =J27*40%+I27*30%+H27*10%+G27*10%+F27*10% -> 0.097028976 | L27: =K27*40%+J27*30%+I27*10%+H27*10%+G27*10% -> 0.097485329 | M27: =L27*40%+K27*30%+J27*10%+I27*10%+H27*10% -> 0.095285245 | N27: =M27*40%+L27*30%+K27*10%+J27*10%+I27*10% -> 0.094997486
B28: iv. Other financial assets | C28: =C8*365/'Profit & Loss Statement'!C$5 -> 8.9062467 | D28: =D8*365/'Profit & Loss Statement'!D$5 -> 43.8413 | E28: =E8*365/'Profit & Loss Statement'!E$5 -> 3.183981 | F28: =F8*365/'Profit & Loss Statement'!F$5 -> 6.8672199 | G28: =G8*365/'Profit & Loss Statement'!G$5 -> 10.714876 | H28: =H8*365/'Profit & Loss Statement'!H$5 -> 8.0206908 | I28: =I8*365/'Revenue Model'!I$3 -> 8.7970717 | J28: =I28*50%+H28*30%+G28*10%+F28*10% -> 8.5629527 | K28: =J28*50%+I28*30%+H28*10%+G28*10% -> 8.7941546 | L28: =K28*50%+J28*30%+I28*10%+H28*10% -> 8.6477393 | M28: =L28*50%+K28*30%+J28*10%+I28*10% -> 8.6981185 | N28: =M28*50%+L28*30%+K28*10%+J28*10% -> 8.6790918
B29: Other assets | C29: =C9*365/'Profit & Loss Statement'!C$5 -> 11.115246 | D29: =D9*365/'Profit & Loss Statement'!D$5 -> 5.32946 | E29: =E9*365/'Profit & Loss Statement'!E$5 -> 6.392083 | F29: =F9*365/'Profit & Loss Statement'!F$5 -> 4.9688797 | G29: =G9*365/'Profit & Loss Statement'!G$5 -> 6.0371901 | H29: =H9*365/'Profit & Loss Statement'!H$5 -> 4.8087155 | I29: =I9*365/'Revenue Model'!I$3 -> 6.4530728 | J29: =I29*40%+H29*30%+G29*10%+F29*10%+E29*10% -> 5.763659 | K29: =J29*40%+I29*30%+H29*10%+G29*10%+F29*10% -> 5.822864 | L29: =K29*40%+J29*30%+I29*10%+H29*10%+G29*10% -> 5.7881411 | M29: =L29*40%+K29*30%+J29*10%+I29*10%+H29*10% -> 5.7646604 | N29: =M29*40%+L29*30%+K29*10%+J29*10%+I29*10% -> 5.8462661
B30: Current Liabilities as days of sales | C30: =C23 -> FY18 | D30: =D23 -> FY19 | E30: =E23 -> FY20 | F30: =F23 -> FY21 | G30: =G23 -> FY22 | H30: =H23 -> FY23 | I30: =I23 -> FY24 | J30: =J23 -> FY25E | ... N30: =N23 -> FY29E
B31: Outstanding Dues of creditors & Enterprises | C31: =C12*365/'Profit & Loss Statement'!C$5 -> 4.2696906 | D31: =D12*365/'Profit & Loss Statement'!D$5 -> 6.596907 | E31: =E12*365/'Profit & Loss Statement'!E$5 -> 36.181602 | F31: =F12*365/'Profit & Loss Statement'!F$5 -> 52.738589 | G31: =G12*365/'Profit & Loss Statement'!G$5 -> 40.35124 | H31: =H12*365/'Profit & Loss Statement'!H$5 -> 42.153323 | I31: =I12*365/'Profit & Loss Statement'!I$5 -> 43.710048 | J31: =I31*40%+H31*30%+G31*10%+F31*10%+E31*10% -> 43.057159 | K31: =J31*40%+I31*30%+H31*10%+G31*10%+F31*10% -> 43.860193 | L31: =K31*40%+J31*30%+I31*10%+H31*10%+G31*10% -> 43.082686 | M31: =L31*40%+K31*30%+J31*10%+I31*10%+H31*10% -> 43.283186 | N31: =M31*40%+L31*30%+K31*10%+J31*10%+I31*10% -> 43.30082
B32: Financial Liabilities
B33: i. Borrowings | C33: =C14*365/'Profit & Loss Statement'!C$5 -> 53.507731 | D33: =D14*365/'Profit & Loss Statement'!D$5 -> 37.170201 | E33: =E14*365/'Profit & Loss Statement'!E$5 -> 0.51136664 | F33: =F14*365/'Profit & Loss Statement'!F$5 -> 2.5363071 | G33: =G14*365/'Profit & Loss Statement'!G$5 -> 1.5785124 | H33: =H14*365/'Profit & Loss Statement'!H$5 -> 3.7483321 | I33: =I14*365/'Profit & Loss Statement'!I$5 -> 0.084908853 | J33: =I33*40%+H33*30%+G33*10%+F33*10%+E33*10% -> 1.6210818 | K33: =J33*40%+I33*30%+H33*10%+G33*10%+F33*10% -> 1.4602205 | L33: =K33*40%+J33*30%+I33*10%+H33*10%+G33*10% -> 1.6115881 | M33: =L33*40%+K33*30%+J33*10%+I33*10%+H33*10% -> 1.6281337 | N33: =M33*40%+L33*30%+K33*10%+J33*10%+I33*10% -> 1.451351
B34: ii. Lease Liabilities | C34: =C15*365/'Profit & Loss Statement'!C$5 -> 11.365026 | D34: =D15*365/'Profit & Loss Statement'!D$5 -> 9.7809811 | E34: =E15*365/'Profit & Loss Statement'!E$5 -> 0.048242136 | F34: =F15*365/'Profit & Loss Statement'!F$5 -> 0.038381743 | G34: =G15*365/'Profit & Loss Statement'!G$5 -> 0.033057851 | H34: =H15*365/'Profit & Loss Statement'!H$5 -> 0.021577569 | I34: =I15*365/'Profit & Loss Statement'!I$5 -> 0.04631392 | J34: =I34*40%+H34*30%+G34*10%+F34*10%+E34*10% -> 0.036967012 | K34: =J34*40%+I34*30%+H34*10%+G34*10%+F34*10% -> 0.037982697 | L34: =K34*40%+J34*30%+I34*10%+H34*10%+G34*10% -> 0.036378116 | M34: =L34*40%+K34*30%+J34*10%+I34*10%+H34*10% -> 0.036431906 | N34: =M34*40%+L34*30%+K34*10%+J34*10%+I34*10% -> 0.03761256
B35: iii. Trade payables | C35: =C16*365/'Profit & Loss Statement'!C$5 -> 19.498514 | D35: =D16*365/'Profit & Loss Statement'!D$5 -> 17.793719 | E35: =E16*365/'Profit & Loss Statement'!E$5 -> 0 | F35: =F16*365/'Profit & Loss Statement'!F$5 -> 0 | G35: =G16*365/'Profit & Loss Statement'!G$5 -> 0 | H35: =H16*365/'Profit & Loss Statement'!H$5 -> 0 | I35: =I16*365/'Profit & Loss Statement'!I$5 -> 0 | J35: =I35*40%+H35*30%+G35*10%+F35*10%+E35*10% -> 0 | K35: =J35*40%+I35*30%+H35*10%+G35*10%+F35*10% -> 0 | L35: =K35*40%+J35*30%+I35*10%+H35*10%+G35*10% -> 0 | M35: =L35*40%+K35*30%+J35*10%+I35*10%+H35*10% -> 0 | N35: =M35*40%+L35*30%+K35*10%+J35*10%+I35*10% -> 0
B36: iv. Other Financial liabilities | C36: =C17*365/'Profit & Loss Statement'!C$5 -> 234.23195 | D36: =D17*365/'Profit & Loss Statement'!D$5 -> 185.04726 | E36: =E17*365/'Profit & Loss Statement'!E$5 -> 4.3610891 | F36: =F17*365/'Profit & Loss Statement'!F$5 -> 6.5975104 | G36: =G17*365/'Profit & Loss Statement'!G$5 -> 8.3760331 | H36: =H17*365/'Profit & Loss Statement'!H$5 -> 7.0589477 | I36: =I17*365/'Profit & Loss Statement'!I$5 -> 5.7223421 | J36: =I36*40%+H36*30%+G36*10%+F36*10%+E36*10% -> 6.3400844 | K36: =J36*40%+I36*30%+H36*10%+G36*10%+F36*10% -> 6.4559855 | L36: =K36*40%+J36*30%+I36*10%+H36*10%+G36*10% -> 6.6001518 | M36: =L36*40%+K36*30%+J36*10%+I36*10%+H36*10% -> 6.4889938 | N36: =M36*40%+L36*30%+K36*10%+J36*10%+I36*10% -> 6.4274842
B37: Provisions | C37: =C18*365/'Profit & Loss Statement'!C$5 -> 6.400633 | D37: =D18*365/'Profit & Loss Statement'!D$5 -> 6.1703029 | E37: =E18*365/'Profit & Loss Statement'!E$5 -> 3.2852895 | F37: =F18*365/'Profit & Loss Statement'!F$5 -> 3.8537344 | G37: =G18*365/'Profit & Loss Statement'!G$5 -> 3.5578512 | H37: =H18*365/'Profit & Loss Statement'!H$5 -> 3.3383582 | I37: =I18*365/'Profit & Loss Statement'!I$5 -> 3.3757701 | J37: =I37*40%+H37*30%+G37*10%+F37*10%+E37*10% -> 3.421503 | K37: =J37*40%+I37*30%+H37*10%+G37*10%+F37*10% -> 3.4563267 | L37: =K37*40%+J37*30%+I37*10%+H37*10%+G37*10% -> 3.4361795 | M37: =L37*40%+K37*30%+J37*10%+I37*10%+H37*10% -> 3.424933 | N37: =M37*40%+L37*30%+K37*10%+J37*10%+I37*10% -> 3.426187
B38: Other current liabilities | C38: =C19*365/'Profit & Loss Statement'!C$5 -> 5.2375912 | D38: =D19*365/'Profit & Loss Statement'!D$5 -> 4.5504438 | E38: =E19*365/'Profit & Loss Statement'!E$5 -> 6.7973169 | F38: =F19*365/'Profit & Loss Statement'!F$5 -> 13.900415 | G38: =G19*365/'Profit & Loss Statement'!G$5 -> 11.855372 | H38: =H19*365/'Profit & Loss Statement'!H$5 -> 10.286336 | I38: =I19*365/'Profit & Loss Statement'!I$5 -> 10.742256 | J38: =I38*40%+H38*30%+G38*10%+F38*10%+E38*10% -> 10.638114 | K38: =J38*40%+I38*30%+H38*10%+G38*10%+F38*10% -> 11.082135 | L38: =K38*40%+J38*30%+I38*10%+H38*10%+G38*10% -> 10.912684 | M38: =L38*40%+K38*30%+J38*10%+I38*10%+H38*10% -> 10.856385 | N38: =M38*40%+L38*30%+K38*10%+J38*10%+I38*10% -> 10.86261
B41: Debt Schedule | C41: =C30 -> FY18 | D41: =D30 -> FY19 | E41: =E30 -> FY20 | F41: =F30 -> FY21 | G41: =G30 -> FY22 | H41: =H30 -> FY23 | I41: =I30 -> FY24 | J41: =J30 -> FY25E | ... N41: =N30 -> FY29E
A42: B/S | B42: Long term Borrowings | C42: ='Balance Sheet'!C41 -> 1483 | D42: ='Balance Sheet'!D41 -> 850 | E42: ='Balance Sheet'!E41 -> 5 | F42: ='Balance Sheet'!F41 -> 2.8 | G42: ='Balance Sheet'!G41 -> 0 | H42: ='Balance Sheet'!H41 -> 0 | I42: ='Balance Sheet'!I41 -> 0 | J42: =AVERAGE(E42:I42)/AVERAGE(E$44:I$44)*J$44 -> 0.12099114 | K42: =AVERAGE(F42:J42)/AVERAGE(F$44:J$44)*K$44 -> 0.049258597 | L42: =AVERAGE(G42:K42)/AVERAGE(G$44:K$44)*L$44 -> 0.0038212058 | M42: =AVERAGE(H42:L42)/AVERAGE(H$44:L$44)*M$44 -> 0.005140706 | N42: =AVERAGE(I42:M42)/AVERAGE(I$44:M$44)*N$44 -> 0.041393374
A43: B/S | B43: Short Term Borrowing | C43: ='Balance Sheet'!C50 -> 6855 | D43: ='Balance Sheet'!D50 -> 6012 | E43: ='Balance Sheet'!E50 -> 106 | F43: ='Balance Sheet'!F50 -> 489 | G43: ='Balance Sheet'!G50 -> 382 | H43: ='Balance Sheet'!H50 -> 1216 | I43: ='Balance Sheet'!I50 -> 33 | J43: =AVERAGE(E43:I43)/AVERAGE(E$44:I$44)*J$44 -> 34.529009 | K43: =AVERAGE(F43:J43)/AVERAGE(F$44:J$44)*K$44 -> 36.333241 | L43: =AVERAGE(G43:K43)/AVERAGE(G$44:K$44)*L$44 -> 38.197804 | M43: =AVERAGE(H43:L43)/AVERAGE(H$44:L$44)*M$44 -> 40.106566 | N43: =AVERAGE(I43:M43)/AVERAGE(I$44:M$44)*N$44 -> 42.075898 | P43: Total Debt | Q43: 2 | R43: B/L Sheet
...

Sheet Profit & Loss Statement
B1: Profit & Loss Statement ( All Amount in ₹ cr, unless otherwise stated)
B3: P&L Statement | C3: ='Balance Sheet'!C3 -> FY18 | D3: ='Balance Sheet'!D3 -> FY19 | E3: ='Balance Sheet'!E3 -> FY20 | F3: ='Balance Sheet'!F3 -> FY21 | G3: ='Balance Sheet'!G3 -> FY22 | H3: ='Balance Sheet'!H3 -> FY23 | I3: ='Balance Sheet'!I3 -> FY24 | J3: ='Balance Sheet'!J3 -> FY25E | ... N3: ='Balance Sheet'!N3 -> FY29E
B4: Income
B5: Revenue from Operations | C5: 46761 | D5: 59036 | E5: 75660 | F5: 70372 | G5: 88330 | H5: 118410 | I5: 141858 | J5: ='Revenue Model'!J3 -> 145471.7 | K5: ='Revenue Model'!K3 -> 145107.7 | L5: ='Revenue Model'!L3 -> 144984.7 | M5: ='Revenue Model'!M3 -> 146605.35 | N5: ='Revenue Model'!N3 -> 149869.7
B6: Other Income | C6: 1672 | D6: 1145 | E6: 3334 | F6: 2936 | G6: 1745 | H6: 2265 | I6: 4094 | J6: =Assumptions!J4 -> 4743.1466 | K6: =Assumptions!K4 -> 4317.6636 | L6: =Assumptions!L4 -> 4006.0408 | M6: =Assumptions!M4 -> 4190.8343 | N6: =Assumptions!N4 -> 4463.6282
B7: Total Income | C7: =SUM(C5:C6) -> 48433 | D7: =SUM(D5:D6) -> 60181 | E7: =SUM(E5:E6) -> 78994 | F7: =SUM(F5:F6) -> 73308 | G7: =SUM(G5:G6) -> 90075 | H7: =SUM(H5:H6) -> 120675 | I7: =SUM(I5:I6) -> 145952 | J7: =SUM(J5:J6) -> 150214.85 | ... N7: =SUM(N5:N6) -> 154333.33
B9: Expense
B10: Selling, General & Administrative Expenses | C10: 35254 | D10: 38505 | E10: 8456 | F10: 8208 | G10: 9437 | H10: 10316 | I10: 12083 | J10: =Assumptions!J9 -> 13403.71 | K10: =Assumptions!K9 -> 14868.779 | L10: =Assumptions!L9 -> 16493.984 | M10: =Assumptions!M9 -> 18296.829 | N10: =Assumptions!N9 -> 20296.731
B11: Depreciation and amortisation | C11: 687 | D11: 2478 | E11: 3528 | F11: 3034 | G11: 2789 | H11: 4846 | I11: 5256 | J11: =Schedules_Populated!J94 -> 6453.3954 | K11: =Schedules_Populated!K94 -> 6977.0334 | L11: =Schedules_Populated!L94 -> 8146.8453 | M11: =Schedules_Populated!M94 -> 9146.126 | N11: =Schedules_Populated!N94 -> 10473.128 | P11: 3rd Linkage
B12: Finance Cost | E12: 134 | F12: 102 | G12: 127 | H12: 252 | I12: 194 | J12: =Schedules_Populated!J53 -> 208.42213 | K12: =Schedules_Populated!K53 -> 208.0012 | L12: =Schedules_Populated!L53 -> 232.38795 | M12: =Schedules_Populated!M53 -> 242.84088 | N12: =Schedules_Populated!N53 -> 240.07668
B13: Total Operating Expenses | C13: =13527+335 -> 13862 | D13: 15048 | E13: =63554-134 -> 63420 | F13: =59948-102 -> 59846 | G13: =76103-127 -> 75976 | H13: =100098-252 -> 99846 | I13: =116699-194 -> 116505 | J13: =Assumptions!J13-208 -> 131387.58 | K13: =Assumptions!K13-208 -> 132129.54 | L13: =Assumptions!L13-232 -> 134530.1 | M13: =Assumptions!M13-243 -> 134387.6 | N13: =Assumptions!N13-240 -> 135386.49
B14: Total Expense | C14: =SUM(C10:C13) -> 49803 | D14: =SUM(D10:D13) -> 56031 | E14: =SUM(E10:E13) -> 75538 | F14: =SUM(F10:F13) -> 71190 | G14: =SUM(G10:G13) -> 88329 | H14: =SUM(H10:H13) -> 115260 | I14: =SUM(I10:I13) -> 134038 | J14: =SUM(J10:J13) -> 151453.11 | ... N14: =SUM(N10:N13) -> 166396.42
B16: EBIT | C16: =C7-C14 -> -1370 | D16: =D7-D14 -> 4150 | E16: 7237 | F16: 5423 | G16: 4824 | H16: 10691 | I16: 17618 | J16: 26427 | K16: 38055 | L16: 51755 | M16: 67281 | N16: 84774 | P16: Capex Schedule
B17: Interest | C17: 0 | D17: 1258 | E17: =E12 -> 134 | F17: =F12 -> 102 | G17: =G12 -> 127 | H17: =H12 -> 252 | I17: =I12 -> 194 | J17: =J12 -> 208.42213 | K17: =K12 -> 208.0012 | L17: =L12 -> 232.38795 | ... N17: =N12 -> 240.07668 | P17: The linkage b/w I/S and B/S through deprn and amortization
B18: Profit before tax | C18: =C16-C17 -> -1370 | D18: =D16-D17 -> 2892 | E18: =E16-E17 -> 7103 | F18: =F16-F17 -> 5321 | G18: =G16-G17 -> 4697 | H18: =H16-H17 -> 10439 | I18: =I16-I17 -> 17424 | J18: =J16-J17 -> 26218.578 | ... N18: =N16-N17 -> 84533.923
B20: Tax expense
B21: Current tax | C21: 0 | D21: 0 | E21: 1376 | F21: 1156 | G21: 1431 | H21: 2249 | I21: 3663
B22: Adjustment of tax relating to earlier periods | C22: 0 | D22: 0 | E22: =0 -> 0 | F22: 0 | G22: 0 | H22: 0 | I22: 0
B23: Deferred tax charge/credit | C23: 0 | D23: -123 | E23: 48 | F23: -224 | G23: -613 | H23: -138 | I23: -273
B24: Net Expense | C24: =SUM(C21:C23) -> 0 | D24: =SUM(D21:D23) -> -123 | E24: =SUM(E21:E23) -> 1424 | F24: =SUM(F21:F23) -> 932 | G24: =SUM(G21:G23) -> 818 | H24: =SUM(H21:H23) -> 2111 | I24: =SUM(I21:I23) -> 3390 | J24: =Assumptions!J18 -> 6599.216 | K24: =Assumptions!K18 -> 9526.0896 | L24: =Assumptions!L18 -> 12968.241 | M24: =Assumptions!M18 -> 16873.505 | N24: =Assumptions!N18 -> 21277.188
B25: Profit for the year | C25: =C18-C24 -> -1370 | D25: =D18-D24 -> 3015 | E25: =E18-E24 -> 5679 | F25: =F18-F24 -> 4389 | G25: =G18-G24 -> 3879 | H25: =H18-H24 -> 8328 | I25: =I18-I24 -> 14034 | J25: =J18-J24 -> 19619.362 | ... N25: =N18-N24 -> 63256.735
J27: 3 months | K27: 9 months
J28: =J25*3/12 -> 4904.8405 | K28: =K25*9/12 -> 21240.682
J29: Total Earning for NTM | K29: =K28+J28 -> 26145.522

Sheet Revenue Model
B1: All Amount are in ₹ cr
B2: Revenue Model | C2: =Assumptions!C2 -> FY18 | D2: =Assumptions!D2 -> FY19 | E2: =Assumptions!E2 -> FY20 | F2: =Assumptions!F2 -> FY21 | G2: =Assumptions!G2 -> FY22 | H2: =Assumptions!H2 -> FY23 | I2: =Assumptions!I2 -> FY24 | J2: =Assumptions!J2 -> FY25E | ... N2: =Assumptions!N2 -> FY29E
B3: Revenue from contracts | C3: ='Profit & Loss Statement'!C5 -> 46761 | D3: ='Profit & Loss Statement'!D5 -> 59036 | E3: ='Profit & Loss Statement'!E5 -> 75660 | F3: ='Profit & Loss Statement'!F5 -> 70372 | G3: ='Profit & Loss Statement'!G5 -> 88330 | H3: ='Profit & Loss Statement'!H5 -> 118410 | I3: ='Profit & Loss Statement'!I5 -> 141858 | J3: =J4+J6 -> 145471.7 | K3: =K4+K6 -> 145107.7 | L3: =L4+L6 -> 144984.7 | M3: =M4+M6 -> 146605.35 | N3: =N4+N6 -> 149869.7
B4: Domestic Sales | C4: =C3*C5 -> 10006.854 | D4: =D3*D5 -> 12987.92 | E4: =E3*E5 -> 70742.1 | F4: =F3*F5 -> 65727.448 | G4: =G3*G5 -> 75963.8 | H4: =H3*H5 -> 94609.59 | I4: =I3*I5 -> 122990.89 | J4: 126617 | K4: 126253 | L4: 126130 | M4: 127750.65 | N4: 131015
B5: As a percentage | C5: 0.214 | D5: 0.22 | E5: 0.935 | F5: 0.934 | G5: 0.86 | H5: 0.799 | I5: 0.867 | J5: =J4/J3 -> 0.87038922 | K5: =K4/K3 -> 0.8700641 | L5: =L4/L3 -> 0.86995386 | M5: =M4/M3 -> 0.87139146 | N5: =N4/N3 -> 0.87419272
B6: Export Sales | C6: =C3*C7 -> 36754.146 | D6: =D3*D7 -> 46048.08 | E6: =E3*E7 -> 4917.9 | F6: =F3*F7 -> 4644.552 | G6: =G3*G7 -> 12366.2 | H6: =H3*H7 -> 23800.41 | I6: =I3*I7 -> 18867.114 | J6: 18854.7 | K6: 18854.7 | L6: 18854.7 | M6: 18854.7 | N6: 18854.7
B7: As a percentage | C7: =1-C5 -> 0.786 | D7: =1-D5 -> 0.78 | E7: =1-E5 -> 0.065 | F7: =1-F5 -> 0.066 | G7: =1-G5 -> 0.14 | H7: =1-H5 -> 0.201 | I7: =1-I5 -> 0.133 | J7: =1-J5 -> 0.12961078 | ... N7: =1-N5 -> 0.12580728
B9: Sales Numbers | C9: =C2 -> FY18 | D9: =D2 -> FY19 | E9: =E2 -> FY20 | F9: =F2 -> FY21 | G9: =G2 -> FY22 | H9: =H2 -> FY23 | I9: FY24 | J9: FY25E
B10: Domestic | C10: 105 | D10: 132 | E10: 1461126 | F10: 1361722 | G10: 1414277 | H10: 1571015 | I10: 1852256 | J10: =AVERAGE(E10:I10)/AVERAGE(E$12:I$12)*J$12 -> 2044575.7 | K10: =AVERAGE(F10:J10)/AVERAGE(F$12:J$12)*K$12 -> 2216688.4 | L10: =AVERAGE(G10:K10)/AVERAGE(G$12:K$12)*L$12 -> 2403981.5 | M10: =AVERAGE(H10:L10)/AVERAGE(H$12:L$12)*M$12 -> 2635701.3 | N10: =AVERAGE(I10:M10)/AVERAGE(I$12:M$12)*N$12 -> 2918663.4
B11: Export | C11: 2148 | D11: 2330 | E11: 102171 | F11: 96139 | G11: 238376 | H11: 395211 | I11: 283067 | J11: =AVERAGE(E11:I11)/AVERAGE(E$12:I$12)*J$12 -> 297586.22 | K11: =AVERAGE(F11:J11)/AVERAGE(F$12:J$12)*K$12 -> 352347.98 | L11: =AVERAGE(G11:K11)/AVERAGE(G$12:K$12)*L$12 -> 413905.57 | M11: =AVERAGE(H11:L11)/AVERAGE(H$12:L$12)*M$12 -> 455141.46 | N11: =AVERAGE(I11:M11)/AVERAGE(I$12:M$12)*N$12 -> 471575.05
B12: Total | C12: =SUM(C10:C11) -> 2253 | D12: =SUM(D10:D11) -> 2462 | E12: =SUM(E10:E11) -> 1563297 | F12: =SUM(F10:F11) -> 1457861 | G12: =SUM(G10:G11) -> 1652653 | H12: =SUM(H10:H11) -> 1966226 | I12: =SUM(I10:I11) -> 2135323 | J12: =I12*(1+J13) -> 2342161.9 | K12: =J12*(1+K13) -> 2569036.3 | L12: =K12*(1+L13) -> 2817887 | M12: =L12*(1+M13) -> 3090842.8 | N12: =M12*(1+N13) -> 3390238.5
B13: Growth in Employees Count | D13: =D12/C12-1 -> 0.092765202 | E13: =-16.1% -> -0.161 | F13: =F12/E12-1 -> -0.067444638 | G13: =G12/F12-1 -> 0.13361493 | H13: =H12/G12-1 -> 0.18973916 | J13: 0.096865392 | K13: 0.096865392 | L13: 0.096865392 | M13: 0.096865392 | N13: 0.096865392
B15: Domestic Sales of Segments | C15: =C2 -> FY18 | D15: =D2 -> FY19 | E15: =E2 -> FY20 | F15: =F2 -> FY21 | G15: =G2 -> FY22 | H15: =H2 -> FY23 | I15: =I2 -> FY24
B16: Mini (Sales) | C16: 0.684 | D16: 0.773 | E16: =E17*E4 -> 12026.157 | F16: =F17*F4 -> 10910.756 | G16: =G17*G4 -> 11394.57 | H16: =H17*H4 -> 11920.808 | I16: =I17*I4 -> 9470.2982 | J16: =I16+0.5% -> 9470.3032 | K16: =J16+0.5% -> 9470.3082 | L16: =K16+0.5% -> 9470.3132 | M16: =L16+0.5% -> 9470.3182 | N16: =M16+0.5% -> 9470.3232
A17: =A14*J12 -> 0 | B17: Mini(% of Domestic Sales) | E17: 0.17 | F17: 0.166 | G17: 0.15 | H17: 0.126 | I17: 0.077 | J17: 0.07 | K17: 0.07 | L17: 0.07 | M17: 0.07 | N17: 0.07
B18: Compact (Sales) | E18: =E19*E4 -> 38129.992 | F18: =F19*F4 -> 34704.093 | G18: =G19*G4 -> 37981.9 | H18: =H19*H4 -> 44088.069 | I18: =I19*I4 -> 54976.926 | J18: =J19*J4 -> 57800.661 | K18: =K19*K4 -> 57034.793 | L18: =L19*L4 -> 56979.227 | ... N18: =N19*N4 -> 59186.026
B19: Compact(% of Domestic Sales) | E19: 0.539 | F19: 0.528 | G19: 0.5 | H19: 0.466 | I19: 0.447 | J19: =AVERAGE(H19:I19) -> 0.4565 | K19: =AVERAGE(I19:J19) -> 0.45175 | L19: =AVERAGE($I$19:K19) -> 0.45175 | M19: =AVERAGE($I$19:L19) -> 0.45175 | N19: =AVERAGE($I$19:M19) -> 0.45175
B20: Mini + Compact (Sales) | E20: =E16+E18 -> 50156.149 | F20: =F16+F18 -> 45614.849 | G20: =G16+G18 -> 49376.47 | H20: =H16+H18 -> 56008.877 | I20: =I16+I18 -> 64447.224 | J20: =J16+J18 -> 67270.964 | K20: =K16+K18 -> 66505.101 | L20: =L16+L18 -> 66449.541 | ... N20: =N16+N18 -> 68656.349
B21: Mid Size (Sales) | E21: =E22*E4 -> 1202.6157 | F21: =F22*F4 -> 657.27448 | G21: =G22*G4 -> 759.638 | H21: =H22*H4 -> 747.41576 | I21: =I22*I4 -> 737.94532 | J21: =J22*J4 -> 879.98815 | K21: =K22*K4 -> 817.48817 | L21: =L22*L4 -> 846.64762 | ... N21: =N22*N4 -> 871.65917
B22: Mid Size(% of Domestic Sales) | E22: 0.017 | F22: 0.01 | G22: 0.01 | H22: 0.0079 | I22: 0.006 | J22: =AVERAGE(H22:I22) -> 0.00695 | K22: =AVERAGE(I22:J22) -> 0.006475 | L22: =AVERAGE(J22:K22) -> 0.0067125 | M22: =AVERAGE(K22:L22) -> 0.00659375 | N22: =AVERAGE(L22:M22) -> 0.006653125
B23: UV's (Sales) | E23: =E24*E4 -> 11389.478 | F23: =F24*F4 -> 11042.211 | G23: =G24*G4 -> 15952.398 | H23: =H24*H4 -> 18732.699 | I23: =I24*I4 -> 42677.837 | J23: =J24*J4 -> 43936.099 | K23: =K24*K4 -> 43809.791 | L23: =L24*L4 -> 43767.11 | ... N23: =N24*N4 -> 45462.205
B24: UV's (% of Domestic Sales) | E24: 0.161 | F24: 0.168 | G24: 0.21 | H24: 0.198 | I24: 0.347 | J24: 0.347 | K24: 0.347 | L24: 0.347 | M24: 0.347 | N24: 0.347
B25: Vans (Sales) | E25: =E26*E4 -> 5730.1101 | F25: =F26*F4 -> 5061.0135 | G25: =G26*G4 -> 6077.104 | H25: =H26*H4 -> 4825.0891 | I25: =I26*I4 -> 9101.3256 | J25: =J26*J4 -> 9192.3942 | K25: =K26*K4 -> 8953.8628 | L25: =L26*L4 -> 8791.7655 | ... N25: =N26*N4 -> 9298.6272
B26: Vans (% of Domestic Sales) | E26: 0.081 | F26: 0.077 | G26: 0.08 | H26: 0.051 | I26: 0.074 | J26: =AVERAGE(E26:I26) -> 0.0726 | K26: =AVERAGE(F26:J26) -> 0.07092 | L26: =AVERAGE(G26:K26) -> 0.069704 | M26: =AVERAGE(H26:L26) -> 0.0676448 | N26: =AVERAGE(I26:M26) -> 0.07097376
B27: LCV (Sales) | E27: =E28*E4 -> 1061.1315 | F27: =F28*F4 -> 1446.0039 | G27: =G28*G4 -> 1519.276 | H27: =H28*H4 -> 1892.1918 | I27: =I28*I4 -> 2213.8359 | J27: =J28*J4 -> 2405.723 | K27: =K28*K4 -> 2499.8094 | L27: =L28*L4 -> 2441.8768 | ... N27: =N28*N4 -> 2499.5566
B28: LCV (% of Domestic Sales) | E28: 0.015 | F28: 0.022 | G28: 0.02 | H28: 0.02 | I28: 0.018 | J28: =AVERAGE(E28:I28) -> 0.019 | K28: =AVERAGE(F28:J28) -> 0.0198 | L28: =AVERAGE(G28:K28) -> 0.01936 | M28: =AVERAGE(H28:L28) -> 0.019232 | N28: =AVERAGE(I28:M28) -> 0.0190784
B29: Other OEM Sales | E29: =E30*E4 -> 1202.6157 | F29: =F30*F4 -> 1840.3685 | G29: =G30*G4 -> 2278.914 | H29: =H30*H4 -> 3216.7261 | I29: =I30*I4 -> 3935.7084 | J29: =J30*J4 -> 3925.127 | K29: =K30*K4 -> 4008.5327 | L29: =L30*L4 -> 4059.8094 | ... N29: =N30*N4 -> 4148.9789
B30: OEM (% of Domestic Sales) | E30: 0.017 | F30: 0.028 | G30: 0.03 | H30: 0.034 | I30: 0.032 | J30: =AVERAGE(F30:I30) -> 0.031 | K30: =AVERAGE(G30:J30) -> 0.03175 | L30: =AVERAGE(H30:K30) -> 0.0321875 | M30: =AVERAGE(I30:L30) -> 0.031734375 | N30: =AVERAGE(J30:M30) -> 0.031667969

Sheet Assumptions
B2: Revenue Assumptions | C2: ='Profit & Loss Statement'!C3 -> FY18 | D2: ='Profit & Loss Statement'!D3 -> FY19 | E2: ='Profit & Loss Statement'!E3 -> FY20 | F2: ='Profit & Loss Statement'!F3 -> FY21 | G2: ='Profit & Loss Statement'!G3 -> FY22 | H2: ='Profit & Loss Statement'!H3 -> FY23 | I2: ='Profit & Loss Statement'!I3 -> FY24 | J2: ='Profit & Loss Statement'!J3 -> FY25E | ... N2: ='Profit & Loss Statement'!N3 -> FY29E
B3: Revenue from contracts with customers | C3: ='Profit & Loss Statement'!C5 -> 46761 | D3: ='Profit & Loss Statement'!D5 -> 59036 | E3: ='Profit & Loss Statement'!E5 -> 75660 | F3: ='Profit & Loss Statement'!F5 -> 70372 | G3: ='Profit & Loss Statement'!G5 -> 88330 | H3: ='Profit & Loss Statement'!H5 -> 118410 | I3: ='Profit & Loss Statement'!I5 -> 141858 | J3: ='Revenue Model'!J3 -> 145471.7 | K3: ='Revenue Model'!K3 -> 145107.7 | L3: ='Revenue Model'!L3 -> 144984.7 | M3: ='Revenue Model'!M3 -> 146605.35 | N3: ='Revenue Model'!N3 -> 149869.7
B4: Other Income | C4: ='Profit & Loss Statement'!C6 -> 1672 | D4: ='Profit & Loss Statement'!D6 -> 1145 | E4: ='Profit & Loss Statement'!E6 -> 3334 | F4: ='Profit & Loss Statement'!F6 -> 2936 | G4: ='Profit & Loss Statement'!G6 -> 1745 | H4: ='Profit & Loss Statement'!H6 -> 2265 | I4: ='Profit & Loss Statement'!I6 -> 4094 | J4: =J5*AVERAGE(I3:J3) -> 4743.1466 | K4: =K5*AVERAGE(J3:K3) -> 4317.6636 | L4: =L5*AVERAGE(K3:L3) -> 4006.0408 | M4: =M5*AVERAGE(L3:M3) -> 4190.8343 | N4: =N5*AVERAGE(M3:N3) -> 4463.6282
B5: As a % of Total Revenue | D5: =D4/C4-1 -> -0.31519139 | E5: =E4/AVERAGE(D3:E3) -> 0.049504068 | F5: =F4/AVERAGE(E3:F3) -> 0.040210365 | G5: =G4/AVERAGE(F3:G3) -> 0.021990901 | H5: =H4/AVERAGE(G3:H3) -> 0.02191158 | I5: =I4/AVERAGE(H3:I3) -> 0.03145988 | J5: =AVERAGE(E5:I5) -> 0.033015359 | K5: =AVERAGE(F5:J5) -> 0.029717617 | L5: =AVERAGE(G5:K5) -> 0.027619067 | M5: =AVERAGE(H5:L5) -> 0.028744701 | N5: =AVERAGE(I5:M5) -> 0.030111325
B6: Total | C6: =C3+C4 -> 48433 | D6: =D3+D4 -> 60181 | E6: =E3+E4 -> 78994 | F6: =F3+F4 -> 73308 | G6: =G3+G4 -> 90075 | H6: =H3+H4 -> 120675 | I6: =I3+I4 -> 145952 | J6: =J3+J4 -> 150214.85 | ... N6: =N3+N4 -> 154333.33
B8: Other P&L Assumptions: | E8: =E2 -> FY20 | F8: =F2 -> FY21 | G8: =G2 -> FY22 | H8: =H2 -> FY23 | I8: =I2 -> FY24
B9: Selling, General & Administrative Expenses | C9: ='Profit & Loss Statement'!C10 -> 35254 | D9: ='Profit & Loss Statement'!D10 -> 38505 | E9: ='Profit & Loss Statement'!E10 -> 8456 | F9: ='Profit & Loss Statement'!F10 -> 8208 | G9: ='Profit & Loss Statement'!G10 -> 9437 | H9: ='Profit & Loss Statement'!H10 -> 10316 | I9: ='Profit & Loss Statement'!I10 -> 12083 | J9: =J10*J11 -> 13403.71 | K9: =K10*K11 -> 14868.779 | L9: =L10*L11 -> 16493.984 | M9: =M10*M11 -> 18296.829 | N9: =N10*N11 -> 20296.731
B10: Employee Count | C10: ='Revenue Model'!C12 -> 2253 | D10: ='Revenue Model'!D12 -> 2462 | E10: ='Revenue Model'!E12 -> 1563297 | F10: ='Revenue Model'!F12 -> 1457861 | G10: ='Revenue Model'!G12 -> 1652653 | H10: ='Revenue Model'!H12 -> 1966226 | I10: ='Revenue Model'!I12 -> 2135323 | J10: ='Revenue Model'!J12 -> 2342161.9 | ... N10: ='Revenue Model'!N12 -> 3390238.5
B11: Cost per employee | C11: =C9/C10 -> 15.647581 | D11: =D9/D10 -> 15.639724 | E11: =E9/E10 -> 0.0054090809 | F11: =F9/F10 -> 0.0056301664 | G11: =G9/G10 -> 0.0057102126 | H11: =H9/H10 -> 0.0052465993 | I11: =I9/I10 -> 0.0056586287 | J11: =I11*(1+J12) -> 0.0057227942 | K11: =J11*(1+K12) -> 0.0057876873 | L11: =K11*(1+L12) -> 0.0058533162 | M11: =L11*(1+M12) -> 0.0059196893 | N11: =M11*(1+N12) -> 0.0059868151
B12: Growth Rate of expense per employee | G12: 0.01x(1+CAGR)^4 = 0.01 | I12: =(I11/E11)^(1/4)-1 -> 0.011339406 | J12: =(I11/E11)^(1/4)-1 -> 0.011339406 | K12: =(I11/E11)^(1/4)-1 -> 0.011339406 | L12: =(I11/E11)^(1/4)-1 -> 0.011339406 | M12: =(I11/E11)^(1/4)-1 -> 0.011339406 | N12: =(I11/E11)^(1/4)-1 -> 0.011339406
B13: Total Operating Expenses | C13: ='Profit & Loss Statement'!C13 -> 13862 | D13: ='Profit & Loss Statement'!D13 -> 15048 | E13: ='Profit & Loss Statement'!E13 -> 63420 | F13: ='Profit & Loss Statement'!F13 -> 59846 | G13: ='Profit & Loss Statement'!G13 -> 75976 | H13: ='Profit & Loss Statement'!H13 -> 99846 | I13: ='Profit & Loss Statement'!I13 -> 116505 | J13: =J14*AVERAGE(I3:J3) -> 131595.58 | K13: =K14*AVERAGE(J3:K3) -> 132337.54 | L13: =L14*AVERAGE(K3:L3) -> 134762.1 | M13: =M14*AVERAGE(L3:M3) -> 134630.6 | N13: =N14*AVERAGE(M3:N3) -> 135626.49
B14: As a percent of revenue | C14: =C13/C3 -> 0.29644362 | D14: =D13/D3 -> 0.25489532 | E14: =E13/AVERAGE(D3:E3) -> 0.94167607 | F14: =F13/AVERAGE(E3:F3) -> 0.81962857 | G14: =G13/AVERAGE(F3:G3) -> 0.95746745 | H14: =H13/AVERAGE(G3:H3) -> 0.96590887 | I14: =I13/AVERAGE(H3:I3) -> 0.89526949 | J14: =AVERAGE(E14:I14) -> 0.91599009 | K14: =AVERAGE(F14:J14) -> 0.9108529 | L14: =AVERAGE(G14:K14) -> 0.92909776 | M14: =AVERAGE(H14:L14) -> 0.92342382 | N14: =AVERAGE(I14:M14) -> 0.91492681
B15: Exceptional items- Impairment of goodwill | C15: ='Profit & Loss Statement'!C17 -> 0 | D15: ='Profit & Loss Statement'!D17 -> 1258 | E15: ='Profit & Loss Statement'!E17 -> 134 | F15: ='Profit & Loss Statement'!F17 -> 102 | G15: ='Profit & Loss Statement'!G17 -> 127 | H15: ='Profit & Loss Statement'!H17 -> 252 | I15: ='Profit & Loss Statement'!I17 -> 194 | J15: 0 | K15: 0 | L15: 0 | M15: 0 | N15: 0
B16: Profit before tax | E16: ='Profit & Loss Statement'!E18 -> 7103 | F16: ='Profit & Loss Statement'!F18 -> 5321 | G16: ='Profit & Loss Statement'!G18 -> 4697 | H16: ='Profit & Loss Statement'!H18 -> 10439 | I16: ='Profit & Loss Statement'!I18 -> 17424 | J16: ='Profit & Loss Statement'!J18 -> 26218.578 | K16: ='Profit & Loss Statement'!K18 -> 37846.999 | L16: ='Profit & Loss Statement'!L18 -> 51522.612 | ... N16: ='Profit & Loss Statement'!N18 -> 84533.923
B17: Tax Rate | J17: 0.2517 | K17: 0.2517 | L17: 0.2517 | M17: 0.2517 | N17: 0.2517 | P17: Corporate tax rate in india
B18: Tax expense | J18: =J16*J17 -> 6599.216 | K18: =K16*K17 -> 9526.0896 | L18: =L16*L17 -> 12968.241 | M18: =M16*M17 -> 16873.505 | N18: =N16*N17 -> 21277.188 | P18: 0.2517
B21: Other Balance Sheet Assumptions | C21: =C2 -> FY18 | D21: =D2 -> FY19 | E21: =E2 -> FY20 | F21: =F2 -> FY21 | G21: =G2 -> FY22 | H21: =H2 -> FY23 | I21: =I2 -> FY24 | J21: =J2 -> FY25E | ... N21: =N2 -> FY29E
B22: Capital work in progress | C22: ='Balance Sheet'!C6 -> 14 | D22: ='Balance Sheet'!D6 -> 0 | E22: ='Balance Sheet'!E6 -> 1344 | F22: ='Balance Sheet'!F6 -> 1199 | G22: ='Balance Sheet'!G6 -> 2646 | H22: ='Balance Sheet'!H6 -> 4054 | I22: ='Balance Sheet'!I6 -> 7504 | J22: =I22*40%+H22*30%+G22*10%+F22*10%+E22*10% -> 4736.7 | K22: =J22*40%+I22*30%+H22*10%+G22*10%+F22*10% -> 4935.78 | L22: =K22*40%+J22*30%+I22*10%+H22*10%+G22*10% -> 4815.722 | M22: =L22*40%+K22*30%+J22*10%+I22*10%+H22*10% -> 5036.4928 | N22: =M22*40%+L22*30%+K22*10%+J22*10%+I22*10% -> 5176.9617
B23: Goodwill | C23: ='Balance Sheet'!C7 -> 2961 | D23: ='Balance Sheet'!D7 -> 1736 | E23: ='Balance Sheet'!E7 -> 0 | F23: ='Balance Sheet'!F7 -> 0 | G23: ='Balance Sheet'!G7 -> 0 | H23: ='Balance Sheet'!H7 -> 0 | I23: ='Balance Sheet'!I7 -> 0 | J23: =I23 -> 0 | K23: =J23 -> 0 | L23: =K23 -> 0 | M23: =L23 -> 0 | N23: =M23 -> 0
B24: Intangible assets under development | C24: ='Balance Sheet'!C9 -> 0 | D24: ='Balance Sheet'!D9 -> 17 | E24: ='Balance Sheet'!E9 -> 71 | F24: ='Balance Sheet'!F9 -> 298 | G24: ='Balance Sheet'!G9 -> 290 | H24: ='Balance Sheet'!H9 -> 89 | I24: ='Balance Sheet'!I9 -> 230 | J24: =I24*40%+H24*30%+G24*10%+F24*10%+E24*10% -> 184.6 | K24: =J24*40%+I24*30%+H24*10%+G24*10%+F24*10% -> 210.54 | L24: =K24*40%+J24*30%+I24*10%+H24*10%+G24*10% -> 200.496 | M24: =L24*40%+K24*30%+J24*10%+I24*10%+H24*10% -> 193.7204 | N24: =M24*40%+L24*30%+K24*10%+J24*10%+I24*10% -> 200.15096
B26: Financial Assets
B27: i. Loans | C27: ='Balance Sheet'!C13 -> 585 | D27: ='Balance Sheet'!D13 -> 618 | E27: ='Balance Sheet'!E13 -> 0.2 | F27: ='Balance Sheet'!F13 -> 0.2 | G27: ='Balance Sheet'!G13 -> 0.2 | H27: ='Balance Sheet'!H13 -> 0.2 | I27: ='Balance Sheet'!I13 -> 0.1 | J27: =I27*40%+H27*30%+G27*10%+F27*10%+E27*10% -> 0.16 | K27: =J27*40%+I27*30%+H27*10%+G27*10%+F27*10% -> 0.154 | L27: =K27*40%+J27*30%+I27*10%+H27*10%+G27*10% -> 0.1596 | M27: =L27*40%+K27*30%+J27*10%+I27*10%+H27*10% -> 0.15604 | N27: =M27*40%+L27*30%+K27*10%+J27*10%+I27*10% -> 0.151696
B28: ii. Other Financial assets | C28: ='Balance Sheet'!C14 -> 185 | D28: ='Balance Sheet'!D14 -> 239 | E28: ='Balance Sheet'!E14 -> 36.5 | F28: ='Balance Sheet'!F14 -> 37 | G28: ='Balance Sheet'!G14 -> 37.5 | H28: ='Balance Sheet'!H14 -> 240 | I28: ='Balance Sheet'!I14 -> 298 | J28: =I28*40%+H28*30%+G28*10%+F28*10%+E28*10% -> 202.3 | K28: =J28*40%+I28*30%+H28*10%+G28*10%+F28*10% -> 201.77 | L28: =K28*40%+J28*30%+I28*10%+H28*10%+G28*10% -> 198.948 | M28: =L28*40%+K28*30%+J28*10%+I28*10%+H28*10% -> 214.1402 | N28: =M28*40%+L28*30%+K28*10%+J28*10%+I28*10% -> 215.54748
B29: Income tax assets (net) | C29: ='Balance Sheet'!C15 -> 584 | D29: ='Balance Sheet'!D15 -> 920 | E29: ='Balance Sheet'!E15 -> 0 | F29: ='Balance Sheet'!F15 -> 541 | G29: ='Balance Sheet'!G15 -> 545 | H29: ='Balance Sheet'!H15 -> 605 | I29: ='Balance Sheet'!I15 -> 584 | J29: =I29*40%+H29*30%+G29*10%+F29*10%+E29*10% -> 523.7 | K29: =J29*40%+I29*30%+H29*10%+G29*10%+F29*10% -> 553.78 | L29: =K29*40%+J29*30%+I29*10%+H29*10%+G29*10% -> 552.022 | M29: =L29*40%+K29*30%+J29*10%+I29*10%+H29*10% -> 558.2128 | N29: =M29*40%+L29*30%+K29*10%+J29*10%+I29*10% -> 555.03972
B30: Other Assets | C30: ='Balance Sheet'!C16 -> 40 | D30: ='Balance Sheet'!D16 -> 48 | E30: ='Balance Sheet'!E16 -> 1722 | F30: ='Balance Sheet'!F16 -> 1687 | G30: ='Balance Sheet'!G16 -> 2520 | H30: ='Balance Sheet'!H16 -> 2323 | I30: ='Balance Sheet'!I16 -> 2805 | J30: =I30*40%+H30*30%+G30*10%+F30*10%+E30*10% -> 2411.8 | K30: =J30*40%+I30*30%+H30*10%+G30*10%+F30*10% -> 2459.22 | L30: =K30*40%+J30*30%+I30*10%+H30*10%+G30*10% -> 2472.028 | M30: =L30*40%+K30*30%+J30*10%+I30*10%+H30*10% -> 2480.5572 | N30: =M30*40%+L30*30%+K30*10%+J30*10%+I30*10% -> 2501.4333
B31: Deferred tax assets (net) | C31: ='Balance Sheet'!C17 -> 0 | D31: ='Balance Sheet'!D17 -> 0 | E31: ='Balance Sheet'!E17 -> 0 | F31: ='Balance Sheet'!F17 -> 0 | G31: ='Balance Sheet'!G17 -> 141 | H31: ='Balance Sheet'!H17 -> 279 | I31: ='Balance Sheet'!I17 -> 47 | J31: =I31*40%+H31*30%+G31*10%+F31*10%+E31*10% -> 116.6 | K31: =J31*40%+I31*30%+H31*10%+G31*10%+F31*10% -> 102.74 | L31: =K31*40%+J31*30%+I31*10%+H31*10%+G31*10% -> 122.776 | M31: =L31*40%+K31*30%+J31*10%+I31*10%+H31*10% -> 124.1924 | N31: =M31*40%+L31*30%+K31*10%+J31*10%+I31*10% -> 113.14376
B33: Equity
B34: Equity share capital | C34: ='Balance Sheet'!C34 -> 375 | D34: ='Balance Sheet'!D34 -> 597 | E34: ='Balance Sheet'!E34 -> 151 | F34: ='Balance Sheet'!F34 -> 151 | G34: ='Balance Sheet'!G34 -> 151 | H34: ='Balance Sheet'!H34 -> 157 | I34: ='Balance Sheet'!I34 -> 157 | J34: =I34 -> 157 | K34: =J34 -> 157 | L34: =K34 -> 157 | M34: =L34 -> 157 | N34: =M34 -> 157
B35: Instruments entirely in the nature of equity | C35: ='Balance Sheet'!C35 -> 2229 | D35: ='Balance Sheet'!D35 -> 2230 | E35: ='Balance Sheet'!E35 -> 19 | F35: ='Balance Sheet'!F35 -> 0 | G35: ='Balance Sheet'!G35 -> 0 | H35: ='Balance Sheet'!H35 -> 0 | I35: ='Balance Sheet'!I35 -> 0 | J35: 0 | K35: 0 | L35: 0 | M35: 0 | N35: 0
B36: Other equity (Reserves & Surplus) | C36: ='Balance Sheet'!C36 -> -13492 | D36: ='Balance Sheet'!D36 -> -9432 | E36: ='Balance Sheet'!E36 -> 49262 | F36: ='Balance Sheet'!F36 -> 52350 | G36: ='Balance Sheet'!G36 -> 55182 | H36: ='Balance Sheet'!H36 -> 74443 | I36: ='Balance Sheet'!I36 -> 85479 | J36: =I36+'Profit & Loss Statement'!J25 -> 105098.36 | K36: =J36+'Profit & Loss Statement'!K25 -> 133419.27 | L36: =K36+'Profit & Loss Statement'!L25 -> 171973.64 | M36: =L36+'Profit & Loss Statement'!M25 -> 222138.3 | N36: =M36+'Profit & Loss Statement'!N25 -> 285395.03
B38: Other Financial Liabilities | C38: ='Balance Sheet'!C43 -> 0 | D38: ='Balance Sheet'!D43 -> 0 | E38: ='Balance Sheet'!E43 -> 2116 | F38: ='Balance Sheet'!F43 -> 2129 | G38: ='Balance Sheet'!G43 -> 2181 | H38: ='Balance Sheet'!H43 -> 2585 | I38: ='Balance Sheet'!I43 -> 3162 | J38: =I38*40%+H38*30%+G38*10%+F38*10%+E38*10% -> 2682.9 | K38: =J38*40%+I38*30%+H38*10%+G38*10%+F38*10% -> 2711.26 | L38: =K38*40%+J38*30%+I38*10%+H38*10%+G38*10% -> 2682.174 | M38: =L38*40%+K38*30%+J38*10%+I38*10%+H38*10% -> 2729.2376 | N38: =M38*40%+L38*30%+K38*10%+J38*10%+I38*10% -> 2751.9632
B39: Provisions | C39: ='Balance Sheet'!C44 -> 812 | D39: ='Balance Sheet'!D44 -> 940 | E39: ='Balance Sheet'!E44 -> 52 | F39: ='Balance Sheet'!F44 -> 45 | G39: ='Balance Sheet'!G44 -> 84 | H39: ='Balance Sheet'!H44 -> 87 | I39: ='Balance Sheet'!I44 -> 145 | J39: =I39*40%+H39*30%+G39*10%+F39*10%+E39*10% -> 102.2 | K39: =J39*40%+I39*30%+H39*10%+G39*10%+F39*10% -> 105.98 | L39: =K39*40%+J39*30%+I39*10%+H39*10%+G39*10% -> 104.652 | M39: =L39*40%+K39*30%+J39*10%+I39*10%+H39*10% -> 107.0748 | N39: =M39*40%+L39*30%+K39*10%+J39*10%+I39*10% -> 109.54352
B40: Deferred tax liabilities (net) | C40: ='Balance Sheet'!C45 -> 123 | D40: ='Balance Sheet'!D45 -> 0 | E40: ='Balance Sheet'!E45 -> 658 | F40: ='Balance Sheet'!F45 -> 445 | G40: ='Balance Sheet'!G45 -> 0 | H40: ='Balance Sheet'!H45 -> 321 | I40: ='Balance Sheet'!I45 -> 389 | J40: =I40*40%+H40*30%+G40*10%+F40*10%+E40*10% -> 362.2 | K40: =J40*40%+I40*30%+H40*10%+G40*10%+F40*10% -> 338.18 | L40: =K40*40%+J40*30%+I40*10%+H40*10%+G40*10% -> 314.932 | M40: =L40*40%+K40*30%+J40*10%+I40*10%+H40*10% -> 334.6468 | N40: =M40*40%+L40*30%+K40*10%+J40*10%+I40*10% -> 337.27632

Sheet WACC
B1: Maruti Suzuki | C1: Nifty 50 | E1: Returns/Maruti | F1: Returns/Nifty 50 | N1: Nifty 100
A2: 45687 | B2: 12000 | C2: =N2*2 -> 23292.301 | K2: CMP (Current Market Price) | L2: 12310.65 | N2: 11646.15
A3: 45686 | B3: 11977.9 | C3: =N3*2 -> 23280.4 | E3: =B3/B2-1 -> -0.0018416667 | F3: =C3/C2-1 -> -0.00051091526 | K3: No. of Shares in Cr | L3: 31.44 | N3: 11640.2
A4: 45685 | B4: 12123.75 | C4: =N4*2 -> 22734.5 | E4: =B4/B3-1 -> 0.012176592 | F4: =C4/C3-1 -> -0.023448926 | N4: 11367.25
A5: 45684 | B5: 11993.85 | C5: =N5*2 -> 22529.1 | E5: =B5/B4-1 -> -0.010714507 | F5: =C5/C4-1 -> -0.0090347441 | I5: =SLOPE(E3:E926,F3:F926) -> 0.00060484148 | N5: 11264.55
A6: 45681 | B6: 11967.9 | C6: =N6*2 -> 22483.199 | E6: =B6/B5-1 -> -0.0021636088 | F6: =C6/C5-1 -> -0.0020373824 | N6: 11241.6
A7: 45680 | B7: 12045.75 | C7: =N7*2 -> 21844.5 | E7: =B7/B6-1 -> 0.0065049006 | F7: =C7/C6-1 -> -0.028407844 | H7: WACC | N7: 10922.25
A8: 45679 | B8: 12020.35 | C8: =N8*2 -> 22352.6 | E8: =B8/B7-1 -> -0.0021086275 | F8: =C8/C7-1 -> 0.023259842 | H8: Beta | I8: =_xlfn.COVARIANCE.S(E3:E251,F3:F251)/_xlfn.VAR.S(F3:F251) -> 0.00060484148 | N8: 11176.3
A9: 45678 | B9: 11883.7 | C9: =N9*2 -> 22730.5 | E9: =B9/B8-1 -> -0.011368221 | F9: =C9/C8-1 -> 0.016906328 | H9: Risk Free Rate | I9: 0.0691 | N9: 11365.25
A10: 45677 | B10: 12020.05 | C10: =N10*2 -> 22707.301 | E10: =B10/B9-1 -> 0.011473699 | F10: =C10/C9-1 -> -0.0010206207 | H10: Equity Risk Premium | I10: 0.0781 | K10: Terminal Growth Rate Calculation | N10: 11353.65
A11: 45674 | B11: 12136.35 | C11: =N11*2 -> 22770.4 | E11: =B11/B10-1 -> 0.0096755005 | F11: =C11/C10-1 -> 0.0027788247 | K11: GDP USA | L11: 0.037 | M11: 0.4 | N11: 11385.2
